<robot name="pendulumCart">

    <!-- links section -->>
    <link name = "link Root">
        <visual>
            <origin xyz = "0 0 0" />
            <geometry>
                <sphere radius="0.1" />
            </geometry>
            <material name = "Root color">
                <color rgba = "1.0 0.1 0.1 1" />
            </material>
        </visual>
    </link>

    <link name = "link A">
        <inertial>
            <origin xyz = "0 0 -0.5" />
            <mass value = "0.5" />
            <inertia ixx = "0.5" iyy = "0.5" izz = "0.5" ixy = "0" ixz = "0" iyz = "0" />
        </inertial>
        <visual>
            <origin xyz = "0 0 -0.5" />
            <geometry>
                <cylinder radius = "0.05" length = "1"  />
            </geometry>
            <material name = "gray B">
                <color rgba = "0.3 0.3 0.3 1" />
            </material>
        </visual>
    </link>

    <!-- joints section -->>

    <joint name = "joint A" type = "continuous">
        <parent link = "link Root" />
        <child link = "link A" />
        <origin xyz = "0 0 -0.05" />
        <axis xyz = "0 1 0" />
        <limit effort="306" lower="-3.141592" upper="3.141592" velocity="500"/>
    </joint>

</robot>
